Workbook
Name BasicA: 'Калькулятор'!$M$8
Name BasicB: 'Калькулятор'!$M$9
Name BasicC: 'Калькулятор'!$M$10
Name BasicD: 'Калькулятор'!$M$11
Name FixedCosts: 'Калькулятор'!$E$12
Name GlobalEAF: 'Факторы'!$D$23
Name HoursMonth: 'Калькулятор'!$E$10
Name InterA: 'Калькулятор'!$M$12
Name InterB: 'Калькулятор'!$M$13
Name InterC: 'Калькулятор'!$M$14
Name InterD: 'Калькулятор'!$M$15
Name IsValid: 'Калькулятор'!$M$6
Name KLOC: 'Калькулятор'!$E$13
Name ModeList: 'Списки'!$A$1:$A$3
Name MonthlyRate: 'Калькулятор'!$E$9
Name NeutralEffort: 'Калькулятор'!$M$16
Name OverheadRate: 'Калькулятор'!$E$11
Name P_ACAP: 'Списки'!$R$1:$R$6
Name P_AEXP: 'Списки'!$T$1:$T$6
Name P_CPLX: 'Списки'!$H$1:$H$7
Name P_DATA: 'Списки'!$F$1:$F$5
Name P_LEXP: 'Списки'!$Z$1:$Z$5
Name P_MODP: 'Списки'!$AB$1:$AB$6
Name P_PCAP: 'Списки'!$V$1:$V$6
Name P_RELY: 'Списки'!$D$1:$D$6
Name P_SCED: 'Списки'!$AF$1:$AF$6
Name P_STOR: 'Списки'!$L$1:$L$5
Name P_TIME: 'Списки'!$J$1:$J$5
Name P_TOOL: 'Списки'!$AD$1:$AD$6
Name P_TURN: 'Списки'!$P$1:$P$5
Name P_VEXP: 'Списки'!$X$1:$X$5
Name P_VIRT: 'Списки'!$N$1:$N$5
Name ProjectMode: 'Калькулятор'!$E$6
Name ProjectTitle: 'Калькулятор'!$E$5
Name R_ACAP: 'Списки'!$Q$1:$Q$5
Name R_AEXP: 'Списки'!$S$1:$S$5
Name R_CPLX: 'Списки'!$G$1:$G$6
Name R_DATA: 'Списки'!$E$1:$E$4
Name R_LEXP: 'Списки'!$Y$1:$Y$4
Name R_MODP: 'Списки'!$AA$1:$AA$5
Name R_PCAP: 'Списки'!$U$1:$U$5
Name R_RELY: 'Списки'!$C$1:$C$5
Name R_SCED: 'Списки'!$AE$1:$AE$5
Name R_STOR: 'Списки'!$K$1:$K$4
Name R_TIME: 'Списки'!$I$1:$I$4
Name R_TOOL: 'Списки'!$AC$1:$AC$5
Name R_TURN: 'Списки'!$O$1:$O$4
Name R_VEXP: 'Списки'!$W$1:$W$4
Name R_VIRT: 'Списки'!$M$1:$M$4
Name SizeRaw: 'Калькулятор'!$E$7
Name SizeUnit: 'Калькулятор'!$E$8
Name UnitList: 'Списки'!$B$1:$B$2

Sheet Калькулятор
A1: COCOMO · ОЦЕНКА ПРОЕКТА
A2: Три уровня модели · трудозатраты, календарный срок, команда и стоимость · без макросов
B4: 01 ПАРАМЕТРЫ ПРОЕКТА
B5: Название проекта | E5: Учебный проект
B6: Тип проекта | E6: Органический | M6: =IFERROR(AND(COUNTIF(ModeList,ProjectMode)=1,ISNUMBER(KLOC),KLOC>0,ISNUMBER(MonthlyRate),MonthlyRate>=0,ISNUMBER(HoursMonth),HoursMonth>0,HoursMonth<=744,ISNUMBER(OverheadRate),OverheadRate>=0,OverheadRate<=10,ISNUMBER(FixedCosts),FixedCosts>=0,COUNT('Факторы'!D7:D21)=15,COUNT('Факторы'!K7:N21)=60,'Фазы'!E14),FALSE) -> TRUE
B7: Объём программного кода | E7: 32
B8: Единица объёма | E8: KLOC — тысячи строк | M8: =IFERROR(VLOOKUP(ProjectMode,'Справочник'!$A$6:$I$8,2,FALSE),0) -> 2.4
B9: Стоимость 1 чел.-месяца | E9: 100000 | M9: =IFERROR(VLOOKUP(ProjectMode,'Справочник'!$A$6:$I$8,3,FALSE),0) -> 1.05
B10: Рабочих часов в месяце | E10: 160 | M10: =IFERROR(VLOOKUP(ProjectMode,'Справочник'!$A$6:$I$8,4,FALSE),0) -> 2.5
B11: Накладные расходы, % | E11: 0 | M11: =IFERROR(VLOOKUP(ProjectMode,'Справочник'!$A$6:$I$8,5,FALSE),0) -> 0.38
B12: Фиксированные затраты | E12: 0 | M12: =IFERROR(VLOOKUP(ProjectMode,'Справочник'!$A$6:$I$8,6,FALSE),0) -> 3.2
B13: Размер для модели, KLOC | E13: =IFERROR(IF(AND(ISNUMBER(SizeRaw),SizeRaw>0,COUNTIF(UnitList,SizeUnit)=1),IF(SizeUnit="LOC — строки",SizeRaw/1000,SizeRaw),""),"") -> 32 | M13: =IFERROR(VLOOKUP(ProjectMode,'Справочник'!$A$6:$I$8,7,FALSE),0) -> 1.05
B14: Общий множитель EAF | E14: ='Факторы'!D23 -> 1 | M14: =IFERROR(VLOOKUP(ProjectMode,'Справочник'!$A$6:$I$8,8,FALSE),0) -> 2.5
M15: =IFERROR(VLOOKUP(ProjectMode,'Справочник'!$A$6:$I$8,9,FALSE),0) -> 0.38
B16: =IF(IsValid,"✓ Расчёт готов. Голубые ячейки доступны для ввода.","Проверьте ввод, оценки факторов и суммы долей на листе «Фазы» (должны быть 100%).") -> ✓ Расчёт готов. Голубые ячейки доступны для ввода. | M16: =IFERROR(InterA*KLOC^InterB,0) -> 121.77481
B18: 02 СРАВНЕНИЕ УРОВНЕЙ
B19: Уровень модели | C19: Труд, чел.-мес. | D19: Труд, чел.-ч. | E19: Срок, мес. | F19: Команда, чел. | G19: Полная стоимость, ₽
B20: Базовый | C20: =IF(IsValid,BasicA*KLOC^BasicB,"") -> 91.331106 | D20: =IF(IsValid,C20*HoursMonth,"") -> 14612.977 | E20: =IF(IsValid,BasicC*C20^BasicD,"") -> 13.89873 | F20: =IF(IsValid,C20/E20,"") -> 6.5711835 | G20: =IF(IsValid,C20*MonthlyRate*(1+OverheadRate)+FixedCosts,"") -> 9133110.6
B21: Промежуточный | C21: =IF(IsValid,NeutralEffort*GlobalEAF,"") -> 121.77481 | D21: =IF(IsValid,C21*HoursMonth,"") -> 19483.969 | E21: =IF(IsValid,InterC*C21^InterD,"") -> 15.504289 | F21: =IF(IsValid,C21/E21,"") -> 7.8542662 | G21: =IF(IsValid,C21*MonthlyRate*(1+OverheadRate)+FixedCosts,"") -> 12177481
B22: Детальный · по стадиям | C22: =IF(IsValid,SUM('Фазы'!I7:I10),"") -> 121.77481 | D22: =IF(IsValid,C22*HoursMonth,"") -> 19483.969 | E22: =IF(IsValid,InterC*C22^InterD,"") -> 15.504289 | F22: =IF(IsValid,C22/E22,"") -> 7.8542662 | G22: =IF(IsValid,C22*MonthlyRate*(1+OverheadRate)+FixedCosts,"") -> 12177481
B24: Стоимость = трудозатраты × ставка × (1 + накладные расходы) + фиксированные затраты.
B25: Команда — средняя расчётная численность; срок — календарные месяцы. Все вычисления ведутся без округления промежуточных значений.
B27: 03 ДЕТАЛИЗАЦИЯ ПО СТАДИЯМ
B28: Стадия | C28: Доля труда | D28: EAF | E28: Труд, чел.-мес. | F28: Срок, мес. | G28: Полная стоимость, ₽
B29: Проектирование продукта | C29: =IF(IsValid,'Фазы'!E7,"") -> 0.16 | D29: =IF(IsValid,'Фазы'!H7,"") -> 1 | E29: =IF(IsValid,'Фазы'!I7,"") -> 19.483969 | F29: =IF(IsValid,'Фазы'!J7,"") -> 2.4806862 | G29: =IF(IsValid,'Фазы'!L7,"") -> 1948396.9
B30: Детальное проектирование | C30: =IF(IsValid,'Фазы'!E8,"") -> 0.24 | D30: =IF(IsValid,'Фазы'!H8,"") -> 1 | E30: =IF(IsValid,'Фазы'!I8,"") -> 29.225954 | F30: =IF(IsValid,'Фазы'!J8,"") -> 3.7210292 | G30: =IF(IsValid,'Фазы'!L8,"") -> 2922595.4
B31: Кодирование и модульные тесты | C31: =IF(IsValid,'Фазы'!E9,"") -> 0.38 | D31: =IF(IsValid,'Фазы'!H9,"") -> 1 | E31: =IF(IsValid,'Фазы'!I9,"") -> 46.274427 | F31: =IF(IsValid,'Фазы'!J9,"") -> 5.8916296 | G31: =IF(IsValid,'Фазы'!L9,"") -> 4627442.7
B32: Интеграция и тестирование | C32: =IF(IsValid,'Фазы'!E10,"") -> 0.22 | D32: =IF(IsValid,'Фазы'!H10,"") -> 1 | E32: =IF(IsValid,'Фазы'!I10,"") -> 26.790458 | F32: =IF(IsValid,'Фазы'!J10,"") -> 3.4109435 | G32: =IF(IsValid,'Фазы'!L10,"") -> 2679045.8
B34: =IF(NOT(IsValid),"Исправьте параметры для получения результатов.",IF(ABS(C21-C22)<0.00000001,"Промежуточный и детальный итоги совпадают: общие оценки стадий дают одинаковый EAF.","Детальный итог учитывает различные факторы затрат по стадиям проекта.")) -> Промежуточный и детальный итоги совпадают: общие оценки стадий дают одинаковый EAF.
B35: Лекция по ссылке недоступна (403). Использованы таблицы COCOMO 81; методика детального уровня и допущения — на листе «Инструкция».
B37: Настроить факторы → | D37: Настроить стадии → | F37: Коэффициенты → | H37: Инструкция →

Sheet Факторы
A1: ФАКТОРЫ · ПРОЕКТ И СТАДИИ
A2: Общие оценки используются в промежуточном уровне. Детальный уровень позволяет выбрать отдельные оценки по стадиям.
A4: «Общий» наследует оценку из столбца C. Голубые ячейки — выпадающие списки. Пояснения факторов — в примечаниях к названиям.
A5: ОБЩАЯ ОЦЕНКА ПРОЕКТА | F5: ОЦЕНКИ ДЛЯ ДЕТАЛЬНОГО УРОВНЯ | K5: РАССЧИТАННЫЕ МНОЖИТЕЛИ СТАДИЙ
A6: Код | B6: Фактор | C6: Уровень | D6: Множитель | F6: Продукт | G6: Детальный проект | H6: Код и модульные тесты | I6: Интеграция и тесты | K6: Продукт | L6: Детальный проект | M6: Код и модульные тесты | N6: Интеграция и тесты
A7: RELY | B7: Требуемая надёжность ПО | C7: Номинальный | D7: =IFERROR(IF(ISNUMBER(INDEX('Справочник'!$C$14:$H$28,1,MATCH(C7,'Справочник'!$C$13:$H$13,0))),INDEX('Справочник'!$C$14:$H$28,1,MATCH(C7,'Справочник'!$C$13:$H$13,0)),""),"") -> 1 | F7: Общий | G7: Общий | H7: Общий | I7: Общий | K7: =IFERROR(IF(F7="Общий",D7,IF(ISNUMBER(INDEX('Справочник'!$C$14:$H$28,1,MATCH(F7,'Справочник'!$C$13:$H$13,0))),INDEX('Справочник'!$C$14:$H$28,1,MATCH(F7,'Справочник'!$C$13:$H$13,0)),"")),"") -> 1 | L7: =IFERROR(IF(G7="Общий",D7,IF(ISNUMBER(INDEX('Справочник'!$C$14:$H$28,1,MATCH(G7,'Справочник'!$C$13:$H$13,0))),INDEX('Справочник'!$C$14:$H$28,1,MATCH(G7,'Справочник'!$C$13:$H$13,0)),"")),"") -> 1 | M7: =IFERROR(IF(H7="Общий",D7,IF(ISNUMBER(INDEX('Справочник'!$C$14:$H$28,1,MATCH(H7,'Справочник'!$C$13:$H$13,0))),INDEX('Справочник'!$C$14:$H$28,1,MATCH(H7,'Справочник'!$C$13:$H$13,0)),"")),"") -> 1 | N7: =IFERROR(IF(I7="Общий",D7,IF(ISNUMBER(INDEX('Справочник'!$C$14:$H$28,1,MATCH(I7,'Справочник'!$C$13:$H$13,0))),INDEX('Справочник'!$C$14:$H$28,1,MATCH(I7,'Справочник'!$C$13:$H$13,0)),"")),"") -> 1
A8: DATA | B8: Размер базы данных | C8: Номинальный | D8: =IFERROR(IF(ISNUMBER(INDEX('Справочник'!$C$14:$H$28,2,MATCH(C8,'Справочник'!$C$13:$H$13,0))),INDEX('Справочник'!$C$14:$H$28,2,MATCH(C8,'Справочник'!$C$13:$H$13,0)),""),"") -> 1 | F8: Общий | G8: Общий | H8: Общий | I8: Общий | K8: =IFERROR(IF(F8="Общий",D8,IF(ISNUMBER(INDEX('Справочник'!$C$14:$H$28,2,MATCH(F8,'Справочник'!$C$13:$H$13,0))),INDEX('Справочник'!$C$14:$H$28,2,MATCH(F8,'Справочник'!$C$13:$H$13,0)),"")),"") -> 1 | L8: =IFERROR(IF(G8="Общий",D8,IF(ISNUMBER(INDEX('Справочник'!$C$14:$H$28,2,MATCH(G8,'Справочник'!$C$13:$H$13,0))),INDEX('Справочник'!$C$14:$H$28,2,MATCH(G8,'Справочник'!$C$13:$H$13,0)),"")),"") -> 1 | M8: =IFERROR(IF(H8="Общий",D8,IF(ISNUMBER(INDEX('Справочник'!$C$14:$H$28,2,MATCH(H8,'Справочник'!$C$13:$H$13,0))),INDEX('Справочник'!$C$14:$H$28,2,MATCH(H8,'Справочник'!$C$13:$H$13,0)),"")),"") -> 1 | N8: =IFERROR(IF(I8="Общий",D8,IF(ISNUMBER(INDEX('Справочник'!$C$14:$H$28,2,MATCH(I8,'Справочник'!$C$13:$H$13,0))),INDEX('Справочник'!$C$14:$H$28,2,MATCH(I8,'Справочник'!$C$13:$H$13,0)),"")),"") -> 1
A9: CPLX | B9: Сложность продукта | C9: Номинальный | D9: =IFERROR(IF(ISNUMBER(INDEX('Справочник'!$C$14:$H$28,3,MATCH(C9,'Справочник'!$C$13:$H$13,0))),INDEX('Справочник'!$C$14:$H$28,3,MATCH(C9,'Справочник'!$C$13:$H$13,0)),""),"") -> 1 | F9: Общий | G9: Общий | H9: Общий | I9: Общий | K9: =IFERROR(IF(F9="Общий",D9,IF(ISNUMBER(INDEX('Справочник'!$C$14:$H$28,3,MATCH(F9,'Справочник'!$C$13:$H$13,0))),INDEX('Справочник'!$C$14:$H$28,3,MATCH(F9,'Справочник'!$C$13:$H$13,0)),"")),"") -> 1 | L9: =IFERROR(IF(G9="Общий",D9,IF(ISNUMBER(INDEX('Справочник'!$C$14:$H$28,3,MATCH(G9,'Справочник'!$C$13:$H$13,0))),INDEX('Справочник'!$C$14:$H$28,3,MATCH(G9,'Справочник'!$C$13:$H$13,0)),"")),"") -> 1 | M9: =IFERROR(IF(H9="Общий",D9,IF(ISNUMBER(INDEX('Справочник'!$C$14:$H$28,3,MATCH(H9,'Справочник'!$C$13:$H$13,0))),INDEX('Справочник'!$C$14:$H$28,3,MATCH(H9,'Справочник'!$C$13:$H$13,0)),"")),"") -> 1 | N9: =IFERROR(IF(I9="Общий",D9,IF(ISNUMBER(INDEX('Справочник'!$C$14:$H$28,3,MATCH(I9,'Справочник'!$C$13:$H$13,0))),INDEX('Справочник'!$C$14:$H$28,3,MATCH(I9,'Справочник'!$C$13:$H$13,0)),"")),"") -> 1
A10: TIME | B10: Ограничения времени выполнения | C10: Номинальный | D10: =IFERROR(IF(ISNUMBER(INDEX('Справочник'!$C$14:$H$28,4,MATCH(C10,'Справочник'!$C$13:$H$13,0))),INDEX('Справочник'!$C$14:$H$28,4,MATCH(C10,'Справочник'!$C$13:$H$13,0)),""),"") -> 1 | F10: Общий | G10: Общий | H10: Общий | I10: Общий | K10: =IFERROR(IF(F10="Общий",D10,IF(ISNUMBER(INDEX('Справочник'!$C$14:$H$28,4,MATCH(F10,'Справочник'!$C$13:$H$13,0))),INDEX('Справочник'!$C$14:$H$28,4,MATCH(F10,'Справочник'!$C$13:$H$13,0)),"")),"") -> 1 | L10: =IFERROR(IF(G10="Общий",D10,IF(ISNUMBER(INDEX('Справочник'!$C$14:$H$28,4,MATCH(G10,'Справочник'!$C$13:$H$13,0))),INDEX('Справочник'!$C$14:$H$28,4,MATCH(G10,'Справочник'!$C$13:$H$13,0)),"")),"") -> 1 | M10: =IFERROR(IF(H10="Общий",D10,IF(ISNUMBER(INDEX('Справочник'!$C$14:$H$28,4,MATCH(H10,'Справочник'!$C$13:$H$13,0))),INDEX('Справочник'!$C$14:$H$28,4,MATCH(H10,'Справочник'!$C$13:$H$13,0)),"")),"") -> 1 | N10: =IFERROR(IF(I10="Общий",D10,IF(ISNUMBER(INDEX('Справочник'!$C$14:$H$28,4,MATCH(I10,'Справочник'!$C$13:$H$13,0))),INDEX('Справочник'!$C$14:$H$28,4,MATCH(I10,'Справочник'!$C$13:$H$13,0)),"")),"") -> 1
A11: STOR | B11: Ограничения оперативной памяти | C11: Номинальный | D11: =IFERROR(IF(ISNUMBER(INDEX('Справочник'!$C$14:$H$28,5,MATCH(C11,'Справочник'!$C$13:$H$13,0))),INDEX('Справочник'!$C$14:$H$28,5,MATCH(C11,'Справочник'!$C$13:$H$13,0)),""),"") -> 1 | F11: Общий | G11: Общий | H11: Общий | I11: Общий | K11: =IFERROR(IF(F11="Общий",D11,IF(ISNUMBER(INDEX('Справочник'!$C$14:$H$28,5,MATCH(F11,'Справочник'!$C$13:$H$13,0))),INDEX('Справочник'!$C$14:$H$28,5,MATCH(F11,'Справочник'!$C$13:$H$13,0)),"")),"") -> 1 | L11: =IFERROR(IF(G11="Общий",D11,IF(ISNUMBER(INDEX('Справочник'!$C$14:$H$28,5,MATCH(G11,'Справочник'!$C$13:$H$13,0))),INDEX('Справочник'!$C$14:$H$28,5,MATCH(G11,'Справочник'!$C$13:$H$13,0)),"")),"") -> 1 | M11: =IFERROR(IF(H11="Общий",D11,IF(ISNUMBER(INDEX('Справочник'!$C$14:$H$28,5,MATCH(H11,'Справочник'!$C$13:$H$13,0))),INDEX('Справочник'!$C$14:$H$28,5,MATCH(H11,'Справочник'!$C$13:$H$13,0)),"")),"") -> 1 | N11: =IFERROR(IF(I11="Общий",D11,IF(ISNUMBER(INDEX('Справочник'!$C$14:$H$28,5,MATCH(I11,'Справочник'!$C$13:$H$13,0))),INDEX('Справочник'!$C$14:$H$28,5,MATCH(I11,'Справочник'!$C$13:$H$13,0)),"")),"") -> 1
A12: VIRT | B12: Изменчивость платформы | C12: Номинальный | D12: =IFERROR(IF(ISNUMBER(INDEX('Справочник'!$C$14:$H$28,6,MATCH(C12,'Справочник'!$C$13:$H$13,0))),INDEX('Справочник'!$C$14:$H$28,6,MATCH(C12,'Справочник'!$C$13:$H$13,0)),""),"") -> 1 | F12: Общий | G12: Общий | H12: Общий | I12: Общий | K12: =IFERROR(IF(F12="Общий",D12,IF(ISNUMBER(INDEX('Справочник'!$C$14:$H$28,6,MATCH(F12,'Справочник'!$C$13:$H$13,0))),INDEX('Справочник'!$C$14:$H$28,6,MATCH(F12,'Справочник'!$C$13:$H$13,0)),"")),"") -> 1 | L12: =IFERROR(IF(G12="Общий",D12,IF(ISNUMBER(INDEX('Справочник'!$C$14:$H$28,6,MATCH(G12,'Справочник'!$C$13:$H$13,0))),INDEX('Справочник'!$C$14:$H$28,6,MATCH(G12,'Справочник'!$C$13:$H$13,0)),"")),"") -> 1 | M12: =IFERROR(IF(H12="Общий",D12,IF(ISNUMBER(INDEX('Справочник'!$C$14:$H$28,6,MATCH(H12,'Справочник'!$C$13:$H$13,0))),INDEX('Справочник'!$C$14:$H$28,6,MATCH(H12,'Справочник'!$C$13:$H$13,0)),"")),"") -> 1 | N12: =IFERROR(IF(I12="Общий",D12,IF(ISNUMBER(INDEX('Справочник'!$C$14:$H$28,6,MATCH(I12,'Справочник'!$C$13:$H$13,0))),INDEX('Справочник'!$C$14:$H$28,6,MATCH(I12,'Справочник'!$C$13:$H$13,0)),"")),"") -> 1
A13: TURN | B13: Время оборота заданий | C13: Номинальный | D13: =IFERROR(IF(ISNUMBER(INDEX('Справочник'!$C$14:$H$28,7,MATCH(C13,'Справочник'!$C$13:$H$13,0))),INDEX('Справочник'!$C$14:$H$28,7,MATCH(C13,'Справочник'!$C$13:$H$13,0)),""),"") -> 1 | F13: Общий | G13: Общий | H13: Общий | I13: Общий | K13: =IFERROR(IF(F13="Общий",D13,IF(ISNUMBER(INDEX('Справочник'!$C$14:$H$28,7,MATCH(F13,'Справочник'!$C$13:$H$13,0))),INDEX('Справочник'!$C$14:$H$28,7,MATCH(F13,'Справочник'!$C$13:$H$13,0)),"")),"") -> 1 | L13: =IFERROR(IF(G13="Общий",D13,IF(ISNUMBER(INDEX('Справочник'!$C$14:$H$28,7,MATCH(G13,'Справочник'!$C$13:$H$13,0))),INDEX('Справочник'!$C$14:$H$28,7,MATCH(G13,'Справочник'!$C$13:$H$13,0)),"")),"") -> 1 | M13: =IFERROR(IF(H13="Общий",D13,IF(ISNUMBER(INDEX('Справочник'!$C$14:$H$28,7,MATCH(H13,'Справочник'!$C$13:$H$13,0))),INDEX('Справочник'!$C$14:$H$28,7,MATCH(H13,'Справочник'!$C$13:$H$13,0)),"")),"") -> 1 | N13: =IFERROR(IF(I13="Общий",D13,IF(ISNUMBER(INDEX('Справочник'!$C$14:$H$28,7,MATCH(I13,'Справочник'!$C$13:$H$13,0))),INDEX('Справочник'!$C$14:$H$28,7,MATCH(I13,'Справочник'!$C$13:$H$13,0)),"")),"") -> 1
A14: ACAP | B14: Способности аналитиков | C14: Номинальный | D14: =IFERROR(IF(ISNUMBER(INDEX('Справочник'!$C$14:$H$28,8,MATCH(C14,'Справочник'!$C$13:$H$13,0))),INDEX('Справочник'!$C$14:$H$28,8,MATCH(C14,'Справочник'!$C$13:$H$13,0)),""),"") -> 1 | F14: Общий | G14: Общий | H14: Общий | I14: Общий | K14: =IFERROR(IF(F14="Общий",D14,IF(ISNUMBER(INDEX('Справочник'!$C$14:$H$28,8,MATCH(F14,'Справочник'!$C$13:$H$13,0))),INDEX('Справочник'!$C$14:$H$28,8,MATCH(F14,'Справочник'!$C$13:$H$13,0)),"")),"") -> 1 | L14: =IFERROR(IF(G14="Общий",D14,IF(ISNUMBER(INDEX('Справочник'!$C$14:$H$28,8,MATCH(G14,'Справочник'!$C$13:$H$13,0))),INDEX('Справочник'!$C$14:$H$28,8,MATCH(G14,'Справочник'!$C$13:$H$13,0)),"")),"") -> 1 | M14: =IFERROR(IF(H14="Общий",D14,IF(ISNUMBER(INDEX('Справочник'!$C$14:$H$28,8,MATCH(H14,'Справочник'!$C$13:$H$13,0))),INDEX('Справочник'!$C$14:$H$28,8,MATCH(H14,'Справочник'!$C$13:$H$13,0)),"")),"") -> 1 | N14: =IFERROR(IF(I14="Общий",D14,IF(ISNUMBER(INDEX('Справочник'!$C$14:$H$28,8,MATCH(I14,'Справочник'!$C$13:$H$13,0))),INDEX('Справочник'!$C$14:$H$28,8,MATCH(I14,'Справочник'!$C$13:$H$13,0)),"")),"") -> 1
A15: AEXP | B15: Опыт в предметной области | C15: Номинальный | D15: =IFERROR(IF(ISNUMBER(INDEX('Справочник'!$C$14:$H$28,9,MATCH(C15,'Справочник'!$C$13:$H$13,0))),INDEX('Справочник'!$C$14:$H$28,9,MATCH(C15,'Справочник'!$C$13:$H$13,0)),""),"") -> 1 | F15: Общий | G15: Общий | H15: Общий | I15: Общий | K15: =IFERROR(IF(F15="Общий",D15,IF(ISNUMBER(INDEX('Справочник'!$C$14:$H$28,9,MATCH(F15,'Справочник'!$C$13:$H$13,0))),INDEX('Справочник'!$C$14:$H$28,9,MATCH(F15,'Справочник'!$C$13:$H$13,0)),"")),"") -> 1 | L15: =IFERROR(IF(G15="Общий",D15,IF(ISNUMBER(INDEX('Справочник'!$C$14:$H$28,9,MATCH(G15,'Справочник'!$C$13:$H$13,0))),INDEX('Справочник'!$C$14:$H$28,9,MATCH(G15,'Справочник'!$C$13:$H$13,0)),"")),"") -> 1 | M15: =IFERROR(IF(H15="Общий",D15,IF(ISNUMBER(INDEX('Справочник'!$C$14:$H$28,9,MATCH(H15,'Справочник'!$C$13:$H$13,0))),INDEX('Справочник'!$C$14:$H$28,9,MATCH(H15,'Справочник'!$C$13:$H$13,0)),"")),"") -> 1 | N15: =IFERROR(IF(I15="Общий",D15,IF(ISNUMBER(INDEX('Справочник'!$C$14:$H$28,9,MATCH(I15,'Справочник'!$C$13:$H$13,0))),INDEX('Справочник'!$C$14:$H$28,9,MATCH(I15,'Справочник'!$C$13:$H$13,0)),"")),"") -> 1
A16: PCAP | B16: Способности программистов | C16: Номинальный | D16: =IFERROR(IF(ISNUMBER(INDEX('Справочник'!$C$14:$H$28,10,MATCH(C16,'Справочник'!$C$13:$H$13,0))),INDEX('Справочник'!$C$14:$H$28,10,MATCH(C16,'Справочник'!$C$13:$H$13,0)),""),"") -> 1 | F16: Общий | G16: Общий | H16: Общий | I16: Общий | K16: =IFERROR(IF(F16="Общий",D16,IF(ISNUMBER(INDEX('Справочник'!$C$14:$H$28,10,MATCH(F16,'Справочник'!$C$13:$H$13,0))),INDEX('Справочник'!$C$14:$H$28,10,MATCH(F16,'Справочник'!$C$13:$H$13,0)),"")),"") -> 1 | L16: =IFERROR(IF(G16="Общий",D16,IF(ISNUMBER(INDEX('Справочник'!$C$14:$H$28,10,MATCH(G16,'Справочник'!$C$13:$H$13,0))),INDEX('Справочник'!$C$14:$H$28,10,MATCH(G16,'Справочник'!$C$13:$H$13,0)),"")),"") -> 1 | M16: =IFERROR(IF(H16="Общий",D16,IF(ISNUMBER(INDEX('Справочник'!$C$14:$H$28,10,MATCH(H16,'Справочник'!$C$13:$H$13,0))),INDEX('Справочник'!$C$14:$H$28,10,MATCH(H16,'Справочник'!$C$13:$H$13,0)),"")),"") -> 1 | N16: =IFERROR(IF(I16="Общий",D16,IF(ISNUMBER(INDEX('Справочник'!$C$14:$H$28,10,MATCH(I16,'Справочник'!$C$13:$H$13,0))),INDEX('Справочник'!$C$14:$H$28,10,MATCH(I16,'Справочник'!$C$13:$H$13,0)),"")),"") -> 1
A17: VEXP | B17: Опыт работы с платформой | C17: Номинальный | D17: =IFERROR(IF(ISNUMBER(INDEX('Справочник'!$C$14:$H$28,11,MATCH(C17,'Справочник'!$C$13:$H$13,0))),INDEX('Справочник'!$C$14:$H$28,11,MATCH(C17,'Справочник'!$C$13:$H$13,0)),""),"") -> 1 | F17: Общий | G17: Общий | H17: Общий | I17: Общий | K17: =IFERROR(IF(F17="Общий",D17,IF(ISNUMBER(INDEX('Справочник'!$C$14:$H$28,11,MATCH(F17,'Справочник'!$C$13:$H$13,0))),INDEX('Справочник'!$C$14:$H$28,11,MATCH(F17,'Справочник'!$C$13:$H$13,0)),"")),"") -> 1 | L17: =IFERROR(IF(G17="Общий",D17,IF(ISNUMBER(INDEX('Справочник'!$C$14:$H$28,11,MATCH(G17,'Справочник'!$C$13:$H$13,0))),INDEX('Справочник'!$C$14:$H$28,11,MATCH(G17,'Справочник'!$C$13:$H$13,0)),"")),"") -> 1 | M17: =IFERROR(IF(H17="Общий",D17,IF(ISNUMBER(INDEX('Справочник'!$C$14:$H$28,11,MATCH(H17,'Справочник'!$C$13:$H$13,0))),INDEX('Справочник'!$C$14:$H$28,11,MATCH(H17,'Справочник'!$C$13:$H$13,0)),"")),"") -> 1 | N17: =IFERROR(IF(I17="Общий",D17,IF(ISNUMBER(INDEX('Справочник'!$C$14:$H$28,11,MATCH(I17,'Справочник'!$C$13:$H$13,0))),INDEX('Справочник'!$C$14:$H$28,11,MATCH(I17,'Справочник'!$C$13:$H$13,0)),"")),"") -> 1
A18: LEXP | B18: Опыт работы с языком | C18: Номинальный | D18: =IFERROR(IF(ISNUMBER(INDEX('Справочник'!$C$14:$H$28,12,MATCH(C18,'Справочник'!$C$13:$H$13,0))),INDEX('Справочник'!$C$14:$H$28,12,MATCH(C18,'Справочник'!$C$13:$H$13,0)),""),"") -> 1 | F18: Общий | G18: Общий | H18: Общий | I18: Общий | K18: =IFERROR(IF(F18="Общий",D18,IF(ISNUMBER(INDEX('Справочник'!$C$14:$H$28,12,MATCH(F18,'Справочник'!$C$13:$H$13,0))),INDEX('Справочник'!$C$14:$H$28,12,MATCH(F18,'Справочник'!$C$13:$H$13,0)),"")),"") -> 1 | L18: =IFERROR(IF(G18="Общий",D18,IF(ISNUMBER(INDEX('Справочник'!$C$14:$H$28,12,MATCH(G18,'Справочник'!$C$13:$H$13,0))),INDEX('Справочник'!$C$14:$H$28,12,MATCH(G18,'Справочник'!$C$13:$H$13,0)),"")),"") -> 1 | M18: =IFERROR(IF(H18="Общий",D18,IF(ISNUMBER(INDEX('Справочник'!$C$14:$H$28,12,MATCH(H18,'Справочник'!$C$13:$H$13,0))),INDEX('Справочник'!$C$14:$H$28,12,MATCH(H18,'Справочник'!$C$13:$H$13,0)),"")),"") -> 1 | N18: =IFERROR(IF(I18="Общий",D18,IF(ISNUMBER(INDEX('Справочник'!$C$14:$H$28,12,MATCH(I18,'Справочник'!$C$13:$H$13,0))),INDEX('Справочник'!$C$14:$H$28,12,MATCH(I18,'Справочник'!$C$13:$H$13,0)),"")),"") -> 1
A19: MODP | B19: Применение методов разработки | C19: Номинальный | D19: =IFERROR(IF(ISNUMBER(INDEX('Справочник'!$C$14:$H$28,13,MATCH(C19,'Справочник'!$C$13:$H$13,0))),INDEX('Справочник'!$C$14:$H$28,13,MATCH(C19,'Справочник'!$C$13:$H$13,0)),""),"") -> 1 | F19: Общий | G19: Общий | H19: Общий | I19: Общий | K19: =IFERROR(IF(F19="Общий",D19,IF(ISNUMBER(INDEX('Справочник'!$C$14:$H$28,13,MATCH(F19,'Справочник'!$C$13:$H$13,0))),INDEX('Справочник'!$C$14:$H$28,13,MATCH(F19,'Справочник'!$C$13:$H$13,0)),"")),"") -> 1 | L19: =IFERROR(IF(G19="Общий",D19,IF(ISNUMBER(INDEX('Справочник'!$C$14:$H$28,13,MATCH(G19,'Справочник'!$C$13:$H$13,0))),INDEX('Справочник'!$C$14:$H$28,13,MATCH(G19,'Справочник'!$C$13:$H$13,0)),"")),"") -> 1 | M19: =IFERROR(IF(H19="Общий",D19,IF(ISNUMBER(INDEX('Справочник'!$C$14:$H$28,13,MATCH(H19,'Справочник'!$C$13:$H$13,0))),INDEX('Справочник'!$C$14:$H$28,13,MATCH(H19,'Справочник'!$C$13:$H$13,0)),"")),"") -> 1 | N19: =IFERROR(IF(I19="Общий",D19,IF(ISNUMBER(INDEX('Справочник'!$C$14:$H$28,13,MATCH(I19,'Справочник'!$C$13:$H$13,0))),INDEX('Справочник'!$C$14:$H$28,13,MATCH(I19,'Справочник'!$C$13:$H$13,0)),"")),"") -> 1
A20: TOOL | B20: Использование инструментов | C20: Номинальный | D20: =IFERROR(IF(ISNUMBER(INDEX('Справочник'!$C$14:$H$28,14,MATCH(C20,'Справочник'!$C$13:$H$13,0))),INDEX('Справочник'!$C$14:$H$28,14,MATCH(C20,'Справочник'!$C$13:$H$13,0)),""),"") -> 1 | F20: Общий | G20: Общий | H20: Общий | I20: Общий | K20: =IFERROR(IF(F20="Общий",D20,IF(ISNUMBER(INDEX('Справочник'!$C$14:$H$28,14,MATCH(F20,'Справочник'!$C$13:$H$13,0))),INDEX('Справочник'!$C$14:$H$28,14,MATCH(F20,'Справочник'!$C$13:$H$13,0)),"")),"") -> 1 | L20: =IFERROR(IF(G20="Общий",D20,IF(ISNUMBER(INDEX('Справочник'!$C$14:$H$28,14,MATCH(G20,'Справочник'!$C$13:$H$13,0))),INDEX('Справочник'!$C$14:$H$28,14,MATCH(G20,'Справочник'!$C$13:$H$13,0)),"")),"") -> 1 | M20: =IFERROR(IF(H20="Общий",D20,IF(ISNUMBER(INDEX('Справочник'!$C$14:$H$28,14,MATCH(H20,'Справочник'!$C$13:$H$13,0))),INDEX('Справочник'!$C$14:$H$28,14,MATCH(H20,'Справочник'!$C$13:$H$13,0)),"")),"") -> 1 | N20: =IFERROR(IF(I20="Общий",D20,IF(ISNUMBER(INDEX('Справочник'!$C$14:$H$28,14,MATCH(I20,'Справочник'!$C$13:$H$13,0))),INDEX('Справочник'!$C$14:$H$28,14,MATCH(I20,'Справочник'!$C$13:$H$13,0)),"")),"") -> 1
A21: SCED | B21: Требуемый график разработки | C21: Номинальный | D21: =IFERROR(IF(ISNUMBER(INDEX('Справочник'!$C$14:$H$28,15,MATCH(C21,'Справочник'!$C$13:$H$13,0))),INDEX('Справочник'!$C$14:$H$28,15,MATCH(C21,'Справочник'!$C$13:$H$13,0)),""),"") -> 1 | F21: Общий | G21: Общий | H21: Общий | I21: Общий | K21: =IFERROR(IF(F21="Общий",D21,IF(ISNUMBER(INDEX('Справочник'!$C$14:$H$28,15,MATCH(F21,'Справочник'!$C$13:$H$13,0))),INDEX('Справочник'!$C$14:$H$28,15,MATCH(F21,'Справочник'!$C$13:$H$13,0)),"")),"") -> 1 | L21: =IFERROR(IF(G21="Общий",D21,IF(ISNUMBER(INDEX('Справочник'!$C$14:$H$28,15,MATCH(G21,'Справочник'!$C$13:$H$13,0))),INDEX('Справочник'!$C$14:$H$28,15,MATCH(G21,'Справочник'!$C$13:$H$13,0)),"")),"") -> 1 | M21: =IFERROR(IF(H21="Общий",D21,IF(ISNUMBER(INDEX('Справочник'!$C$14:$H$28,15,MATCH(H21,'Справочник'!$C$13:$H$13,0))),INDEX('Справочник'!$C$14:$H$28,15,MATCH(H21,'Справочник'!$C$13:$H$13,0)),"")),"") -> 1 | N21: =IFERROR(IF(I21="Общий",D21,IF(ISNUMBER(INDEX('Справочник'!$C$14:$H$28,15,MATCH(I21,'Справочник'!$C$13:$H$13,0))),INDEX('Справочник'!$C$14:$H$28,15,MATCH(I21,'Справочник'!$C$13:$H$13,0)),"")),"") -> 1
A23: EAF = произведение 15 множителей | D23: =IF(COUNT(D7:D21)=15,PRODUCT(D7:D21),"") -> 1 | K23: =IF(COUNT(K7:K21)=15,PRODUCT(K7:K21),"") -> 1 | L23: =IF(COUNT(L7:L21)=15,PRODUCT(L7:L21),"") -> 1 | M23: =IF(COUNT(M7:M21)=15,PRODUCT(M7:M21),"") -> 1 | N23: =IF(COUNT(N7:N21)=15,PRODUCT(N7:N21),"") -> 1
A25: В базовом уровне факторы не используются. Если все стадии наследуют общие оценки, детальные трудозатраты совпадают с промежуточными. Для уточнения выберите другой уровень фактора в нужной стадии.
A28: В этой книге для стадий используются шкалы множителей COCOMO 81 и отдельные оценки факторов. Специальные фазовые таблицы чувствительности из лекции не проверены: лекция недоступна. Методика и границы расчёта описаны на листе «Инструкция».

Sheet Фазы
A1: ДЕТАЛЬНЫЙ УРОВЕНЬ · СТАДИИ
A2: Базовая оценка без факторов × доля стадии × EAF стадии. Итог проекта — сумма трудозатрат стадий.
A4: Доли по умолчанию зависят от типа и размера проекта. Чтобы заменить доли, введите проценты в голубые ячейки; обе суммы должны равняться 100%.
A6: № | B6: Стадия | C6: Доля по таблице | D6: Своя доля труда | E6: Доля труда: итог | F6: Своя доля срока | G6: Доля срока: итог | H6: EAF стадии | I6: Труд, чел.-мес. | J6: Срок, мес. | K6: Трудовые затраты, ₽ | L6: Полная стоимость, ₽
A7: 1 | B7: Проектирование продукта | C7: =IFERROR(SUMIFS('Справочник'!$C$35:$C$48,'Справочник'!$A$35:$A$48,ProjectMode,'Справочник'!$B$35:$B$48,$N$8)*(1-$N$10)+SUMIFS('Справочник'!$C$35:$C$48,'Справочник'!$A$35:$A$48,ProjectMode,'Справочник'!$B$35:$B$48,$N$9)*$N$10,0) -> 0.16 | E7: =IF(D7="",C7,IF(ISNUMBER(D7),D7,-1)) -> 0.16 | G7: =IF(F7="",E7,IF(ISNUMBER(F7),F7,-1)) -> 0.16 | H7: ='Факторы'!K23 -> 1 | I7: =IF(IsValid,NeutralEffort*E7*H7,"") -> 19.483969 | J7: =IF(IsValid,'Калькулятор'!$E$22*G7,"") -> 2.4806862 | K7: =IF(IsValid,I7*MonthlyRate,"") -> 1948396.9 | L7: =IF(IsValid,IF('Калькулятор'!$C$22=0,0,I7/'Калькулятор'!$C$22*'Калькулятор'!$G$22),"") -> 1948396.9 | N7: =IFERROR(MIN(MAX(KLOC,2),IF(ProjectMode="Органический",128,512)),2) -> 32
A8: 2 | B8: Детальное проектирование | C8: =IFERROR(SUMIFS('Справочник'!$D$35:$D$48,'Справочник'!$A$35:$A$48,ProjectMode,'Справочник'!$B$35:$B$48,$N$8)*(1-$N$10)+SUMIFS('Справочник'!$D$35:$D$48,'Справочник'!$A$35:$A$48,ProjectMode,'Справочник'!$B$35:$B$48,$N$9)*$N$10,0) -> 0.24 | E8: =IF(D8="",C8,IF(ISNUMBER(D8),D8,-1)) -> 0.24 | G8: =IF(F8="",E8,IF(ISNUMBER(F8),F8,-1)) -> 0.24 | H8: ='Факторы'!L23 -> 1 | I8: =IF(IsValid,NeutralEffort*E8*H8,"") -> 29.225954 | J8: =IF(IsValid,'Калькулятор'!$E$22*G8,"") -> 3.7210292 | K8: =IF(IsValid,I8*MonthlyRate,"") -> 2922595.4 | L8: =IF(IsValid,IF('Калькулятор'!$C$22=0,0,I8/'Калькулятор'!$C$22*'Калькулятор'!$G$22),"") -> 2922595.4 | N8: =2*4^INT(ROUND(LOG(N7/2,4),12)) -> 32
A9: 3 | B9: Кодирование и модульные тесты | C9: =IFERROR(SUMIFS('Справочник'!$E$35:$E$48,'Справочник'!$A$35:$A$48,ProjectMode,'Справочник'!$B$35:$B$48,$N$8)*(1-$N$10)+SUMIFS('Справочник'!$E$35:$E$48,'Справочник'!$A$35:$A$48,ProjectMode,'Справочник'!$B$35:$B$48,$N$9)*$N$10,0) -> 0.38 | E9: =IF(D9="",C9,IF(ISNUMBER(D9),D9,-1)) -> 0.38 | G9: =IF(F9="",E9,IF(ISNUMBER(F9),F9,-1)) -> 0.38 | H9: ='Факторы'!M23 -> 1 | I9: =IF(IsValid,NeutralEffort*E9*H9,"") -> 46.274427 | J9: =IF(IsValid,'Калькулятор'!$E$22*G9,"") -> 5.8916296 | K9: =IF(IsValid,I9*MonthlyRate,"") -> 4627442.7 | L9: =IF(IsValid,IF('Калькулятор'!$C$22=0,0,I9/'Калькулятор'!$C$22*'Калькулятор'!$G$22),"") -> 4627442.7 | N9: =MIN(N8*4,IF(ProjectMode="Органический",128,512)) -> 128
A10: 4 | B10: Интеграция и тестирование | C10: =IFERROR(SUMIFS('Справочник'!$F$35:$F$48,'Справочник'!$A$35:$A$48,ProjectMode,'Справочник'!$B$35:$B$48,$N$8)*(1-$N$10)+SUMIFS('Справочник'!$F$35:$F$48,'Справочник'!$A$35:$A$48,ProjectMode,'Справочник'!$B$35:$B$48,$N$9)*$N$10,0) -> 0.22 | E10: =IF(D10="",C10,IF(ISNUMBER(D10),D10,-1)) -> 0.22 | G10: =IF(F10="",E10,IF(ISNUMBER(F10),F10,-1)) -> 0.22 | H10: ='Факторы'!N23 -> 1 | I10: =IF(IsValid,NeutralEffort*E10*H10,"") -> 26.790458 | J10: =IF(IsValid,'Калькулятор'!$E$22*G10,"") -> 3.4109435 | K10: =IF(IsValid,I10*MonthlyRate,"") -> 2679045.8 | L10: =IF(IsValid,IF('Калькулятор'!$C$22=0,0,I10/'Калькулятор'!$C$22*'Калькулятор'!$G$22),"") -> 2679045.8 | N10: =IF(N8=N9,0,LN(N7/N8)/LN(N9/N8)) -> 0
A12: ИТОГО | C12: =SUM(C7:C10) -> 1 | E12: =SUM(E7:E10) -> 1 | G12: =SUM(G7:G10) -> 1 | I12: =IF(IsValid,SUM(I7:I10),"") -> 121.77481 | J12: =IF(IsValid,SUM(J7:J10),"") -> 15.504289 | K12: =IF(IsValid,SUM(K7:K10),"") -> 12177481 | L12: =IF(IsValid,SUM(L7:L10),"") -> 12177481
A14: Проверка долей труда и срока | E14: =AND(COUNT(E7:E10)=4,COUNT(G7:G10)=4,MIN(E7:E10)>=0,MAX(E7:E10)<=1,MIN(G7:G10)>=0,MAX(G7:G10)<=1,ABS(SUM(E7:E10)-1)<0.00000001,ABS(SUM(G7:G10)-1)<0.00000001) -> TRUE | F14: =IF(E14,"ОК: обе суммы равны 100%","Ошибка: проверьте проценты; каждая сумма должна быть 100%") -> ОК: обе суммы равны 100%
A16: Срок проекта вычисляется по суммарным трудозатратам: T = c × (ΣEᵢ)^d. Сроки стадий — плановое последовательное распределение T; по умолчанию пропорциональны долям труда. Это допущение планирования, а не отдельная эмпирическая формула COCOMO.
A18: Полная стоимость стадии включает её трудовые затраты и пропорционально распределённые накладные и фиксированные расходы. Планирование и анализ требований до разработки отдельно не оценены; включайте их дополнительной оценкой, если они входят в задание.

Sheet Справочник
A1: СПРАВОЧНИК · COCOMO 81
A2: Открытые таблицы коэффициентов и множителей. Все промежуточные вычисления доступны в строке формул.
A4: 01 КОЭФФИЦИЕНТЫ РЕЖИМОВ
A5: Тип проекта | B5: Базовый: a | C5: Базовый: b | D5: Базовый: c | E5: Базовый: d | F5: Уточнённый: a | G5: Уточнённый: b | H5: Уточнённый: c | I5: Уточнённый: d
A6: Органический | B6: 2.4 | C6: 1.05 | D6: 2.5 | E6: 0.38 | F6: 3.2 | G6: 1.05 | H6: 2.5 | I6: 0.38
A7: Полуразделённый | B7: 3 | C7: 1.12 | D7: 2.5 | E7: 0.35 | F7: 3 | G7: 1.12 | H7: 2.5 | I7: 0.35
A8: Встроенный | B8: 3.6 | C8: 1.2 | D8: 2.5 | E8: 0.32 | F8: 2.8 | G8: 1.2 | H8: 2.5 | I8: 0.32
A10: Базовый: E = a × KLOC^b. Промежуточный: E = a × KLOC^b × EAF. Срок обоих уровней: T = c × E^d.
A12: 02 МНОЖИТЕЛИ ТРУДОЗАТРАТ · 15 ФАКТОРОВ
A13: Код | B13: Фактор | C13: Очень низкий | D13: Низкий | E13: Номинальный | F13: Высокий | G13: Очень высокий | H13: Критический
A14: RELY | B14: Требуемая надёжность ПО | C14: 0.75 | D14: 0.88 | E14: 1 | F14: 1.15 | G14: 1.4 | H14: —
A15: DATA | B15: Размер базы данных | C15: — | D15: 0.94 | E15: 1 | F15: 1.08 | G15: 1.16 | H15: —
A16: CPLX | B16: Сложность продукта | C16: 0.7 | D16: 0.85 | E16: 1 | F16: 1.15 | G16: 1.3 | H16: 1.65
A17: TIME | B17: Ограничения времени выполнения | C17: — | D17: — | E17: 1 | F17: 1.11 | G17: 1.3 | H17: 1.66
A18: STOR | B18: Ограничения оперативной памяти | C18: — | D18: — | E18: 1 | F18: 1.06 | G18: 1.21 | H18: 1.56
A19: VIRT | B19: Изменчивость платформы | C19: — | D19: 0.87 | E19: 1 | F19: 1.15 | G19: 1.3 | H19: —
A20: TURN | B20: Время оборота заданий | C20: — | D20: 0.87 | E20: 1 | F20: 1.07 | G20: 1.15 | H20: —
A21: ACAP | B21: Способности аналитиков | C21: 1.46 | D21: 1.19 | E21: 1 | F21: 0.86 | G21: 0.71 | H21: —
A22: AEXP | B22: Опыт в предметной области | C22: 1.29 | D22: 1.13 | E22: 1 | F22: 0.91 | G22: 0.82 | H22: —
A23: PCAP | B23: Способности программистов | C23: 1.42 | D23: 1.17 | E23: 1 | F23: 0.86 | G23: 0.7 | H23: —
A24: VEXP | B24: Опыт работы с платформой | C24: 1.21 | D24: 1.1 | E24: 1 | F24: 0.9 | G24: — | H24: —
A25: LEXP | B25: Опыт работы с языком | C25: 1.14 | D25: 1.07 | E25: 1 | F25: 0.95 | G25: — | H25: —
A26: MODP | B26: Применение методов разработки | C26: 1.24 | D26: 1.1 | E26: 1 | F26: 0.91 | G26: 0.82 | H26: —
A27: TOOL | B27: Использование инструментов | C27: 1.24 | D27: 1.1 | E27: 1 | F27: 0.91 | G27: 0.83 | H27: —
A28: SCED | B28: Требуемый график разработки | C28: 1.23 | D28: 1.08 | E28: 1 | F28: 1.04 | G28: 1.1 | H28: —
A30: «—» означает, что такой уровень фактора отсутствует в таблице COCOMO 81; в выпадающем списке он не предлагается. EAF — произведение всех 15 множителей.
A33: 03 ДОЛИ ТРУДОЗАТРАТ ПО СТАДИЯМ
A34: Тип проекта | B34: Размер, KLOC | C34: Продукт | D34: Детальный проект | E34: Код и модульные тесты | F34: Интеграция и тесты
A35: Органический | B35: 2 | C35: 0.16 | D35: 0.26 | E35: 0.42 | F35: 0.16
A36: Органический | B36: 8 | C36: 0.16 | D36: 0.25 | E36: 0.4 | F36: 0.19
A37: Органический | B37: 32 | C37: 0.16 | D37: 0.24 | E37: 0.38 | F37: 0.22
A38: Органический | B38: 128 | C38: 0.16 | D38: 0.23 | E38: 0.36 | F38: 0.25
A39: Полуразделённый | B39: 2 | C39: 0.17 | D39: 0.27 | E39: 0.37 | F39: 0.19
A40: Полуразделённый | B40: 8 | C40: 0.17 | D40: 0.26 | E40: 0.36 | F40: 0.21
A41: Полуразделённый | B41: 32 | C41: 0.17 | D41: 0.25 | E41: 0.35 | F41: 0.23
A42: Полуразделённый | B42: 128 | C42: 0.17 | D42: 0.24 | E42: 0.34 | F42: 0.25
A43: Полуразделённый | B43: 512 | C43: 0.17 | D43: 0.23 | E43: 0.33 | F43: 0.27
A44: Встроенный | B44: 2 | C44: 0.18 | D44: 0.28 | E44: 0.34 | F44: 0.2
A45: Встроенный | B45: 8 | C45: 0.18 | D45: 0.27 | E45: 0.33 | F45: 0.22
A46: Встроенный | B46: 32 | C46: 0.18 | D46: 0.26 | E46: 0.32 | F46: 0.24
...

Sheet Инструкция
A1: ИНСТРУКЦИЯ · МЕТОДИКА РАСЧЁТА
A2: Учебный калькулятор конструктивной модели стоимости COCOMO 81. Файл работает в Microsoft Excel без подключения к сети.
B4: 01 КАК ПОЛЬЗОВАТЬСЯ
B5: 1. На листе «Калькулятор» выберите тип проекта, введите размер кода и его единицу, стоимость человеко-месяца и часы работы. Накладные и фиксированные расходы необязательны. 2. На листе «Факторы» выберите уровни 15 факторов. Для отдельных стадий можно заменить «Общий» своей оценкой. 3. На листе «Фазы» при необходимости задайте свои доли труда и срока. В каждом случае сумма должна быть 100%. Результаты пересчитываются автоматически.
B8: Изменять нужно только голубые ячейки. Для процентов вводите, например, 20%. Пустая своя доля наследует автоматическое значение. Проверка ввода отклоняет недопустимые значения. При вставке некорректных данных результаты скрываются до исправления. Защита листов без пароля предохраняет формулы от случайного изменения.
B11: 02 ФОРМУЛЫ ТРЁХ УРОВНЕЙ
B12: БАЗОВЫЙ E = a × KLOC^b; T = c × E^d
B14: ПРОМЕЖУТОЧНЫЙ EAF = EM₁ × EM₂ × … × EM₁₅; E = a × KLOC^b × EAF; T = c × E^d
B16: ДЕТАЛЬНЫЙ — ПОФАЗНАЯ РЕАЛИЗАЦИЯ E₀ = a × KLOC^b; EAFᵢ = произведение 15 множителей стадии i; Eᵢ = E₀ × wᵢ × EAFᵢ; E = ΣEᵢ; T = c × E^d; Σwᵢ = 1
B19: E — человеко-месяцы; T — календарные месяцы; KLOC — тысячи строк кода. Коэффициенты a, b, c, d выбираются по типу проекта на листе «Справочник». Для детального уровня используются коэффициенты промежуточного уровня. Доли wᵢ относятся к номинальным трудозатратам до применения EAF стадии.
B21: Полная стоимость = E × стоимость человеко-месяца × (1 + накладные расходы) + фиксированные затраты. Трудозатраты в часах = E × рабочих часов в месяце. Средняя численность команды = E / T. Полная стоимость каждой стадии распределяется пропорционально её итоговым трудозатратам; сумма совпадает с полной стоимостью детального уровня. Ставка и валюта едины для всех стадий.
B25: 03 ДЕТАЛЬНЫЙ УРОВЕНЬ: ДОПУЩЕНИЯ
B26: Рассчитываются четыре стадии: проектирование продукта, детальное проектирование, кодирование с модульными тестами, интеграция с тестированием. Табличные доли труда зависят от режима и размера проекта; между точками используется интерполяция по логарифму размера, вне диапазона — ближайшая точка. Можно ввести свои доли. Для каждой стадии доступны отдельные оценки всех 15 факторов с теми же шкалами множителей COCOMO 81. Если оценки одинаковы, сумма детальных трудозатрат совпадает с промежуточным уровнем. Длительности стадий являются плановым распределением общего срока. По умолчанию используются доли номинального труда. Можно задать свои доли срока; параллельность стадий не моделируется.
B30: Граница реализации: в классическом Detailed COCOMO могут использоваться специальные таблицы чувствительности факторов по стадиям. Их значения из указанной лекции получить не удалось. Здесь чувствительность задаётся отдельным выбором факторов для стадий; это явная учебная пофазная реализация, соответствие конкретному алгоритму лекции не подтверждено. Планирование и анализ требований до начала разработки отдельно не оценены.
... B50: Лекция из задания: https://de24.adygnet.ru/mod/resource/view.php?id=672, начиная со страницы 19. При подготовке файла сервер вернул HTTP 403; документ прочитать и сверить таблицы не удалось. Если в лекции используются другие коэффициенты или специальные фазовые таблицы, файл нужно сверить с ними перед сдачей.

Sheet Списки
A1: Органический | B1: KLOC — тысячи строк | C1: Очень низкий | D1: Общий | E1: Низкий | F1: Общий | G1: Очень низкий | H1: Общий | I1: Номинальный | J1: Общий | K1: Номинальный | L1: Общий | M1: Низкий | N1: Общий | O1: Низкий | P1: Общий | Q1: Очень низкий | R1: Общий | S1: Очень низкий | T1: Общий | U1: Очень низкий | V1: Общий | W1: Очень низкий | X1: Общий | Y1: Очень низкий | Z1: Общий | AA1: Очень низкий | AB1: Общий | AC1: Очень низкий | AD1: Общий | AE1: Очень низкий | AF1: Общий
A2: Полуразделённый | B2: LOC — строки | C2: Низкий | D2: Очень низкий | E2: Номинальный | F2: Низкий | G2: Низкий | H2: Очень низкий | I2: Высокий | J2: Номинальный | K2: Высокий | L2: Номинальный | M2: Номинальный | N2: Низкий | O2: Номинальный | P2: Низкий | Q2: Низкий | R2: Очень низкий | S2: Низкий | T2: Очень низкий | U2: Низкий | V2: Очень низкий | W2: Низкий | X2: Очень низкий | Y2: Низкий | Z2: Очень низкий | AA2: Низкий | AB2: Очень низкий | AC2: Низкий | AD2: Очень низкий | AE2: Низкий | AF2: Очень низкий
A3: Встроенный | C3: Номинальный | D3: Низкий | E3: Высокий | F3: Номинальный | G3: Номинальный | H3: Низкий | I3: Очень высокий | J3: Высокий | K3: Очень высокий | L3: Высокий | M3: Высокий | N3: Номинальный | O3: Высокий | P3: Номинальный | Q3: Номинальный | R3: Низкий | S3: Номинальный | T3: Низкий | U3: Номинальный | V3: Низкий | W3: Номинальный | X3: Низкий | Y3: Номинальный | Z3: Низкий | AA3: Номинальный | AB3: Низкий | AC3: Номинальный | AD3: Низкий | AE3: Номинальный | AF3: Низкий
C4: Высокий | D4: Номинальный | E4: Очень высокий | F4: Высокий | G4: Высокий | H4: Номинальный | I4: Критический | J4: Очень высокий | K4: Критический | L4: Очень высокий | M4: Очень высокий | N4: Высокий | O4: Очень высокий | P4: Высокий | Q4: Высокий | R4: Номинальный | S4: Высокий | T4: Номинальный | U4: Высокий | V4: Номинальный | W4: Высокий | X4: Номинальный | Y4: Высокий | Z4: Номинальный | AA4: Высокий | AB4: Номинальный | AC4: Высокий | AD4: Номинальный | AE4: Высокий | AF4: Номинальный
C5: Очень высокий | D5: Высокий | F5: Очень высокий | G5: Очень высокий | H5: Высокий | J5: Критический | L5: Критический | N5: Очень высокий | P5: Очень высокий | Q5: Очень высокий | R5: Высокий | S5: Очень высокий | T5: Высокий | U5: Очень высокий | V5: Высокий | X5: Высокий | Z5: Высокий | AA5: Очень высокий | AB5: Высокий | AC5: Очень высокий | AD5: Высокий | AE5: Очень высокий | AF5: Высокий
D6: Очень высокий | G6: Критический | H6: Очень высокий | R6: Очень высокий | T6: Очень высокий | V6: Очень высокий | AB6: Очень высокий | AD6: Очень высокий | AF6: Очень высокий
H7: Критический
